Total number of errors: 2

Here are all the errors:

{"timestamp":"2025-08-24T14:37:47.772266","level":"error","event":"Task failed with exception","logger":"task","error_detail":[{"exc_type":"ConnectionError","exc_value":"HTTPSConnectionPool(host='api.quotable.io', port=443): Max retries exceeded with url: /random (Caused by NameResolutionError(\"<urllib3.connection.HTTPSConnection object at 0x743e7fe5c8c0>: Failed to resolve 'api.quotable.io' ([Errno -2] Name or service not known)\"))","exc_notes":[],"syntax_error":null,"is_cause":false,"frames":[{"filename":"/home/airflow/.local/lib/python3.12/site-packages/airflow/sdk/execution_time/task_runner.py","lineno":890,"name":"run"},{"filename":"/home/airflow/.local/lib/python3.12/site-packages/airflow/sdk/execution_time/task_runner.py","lineno":1177,"name":"_execute_task"},{"filename":"/home/airflow/.local/lib/python3.12/site-packages/airflow/sdk/bases/operator.py","lineno":397,"name":"wrapper"},{"filename":"/home/airflow/.local/lib/python3.12/site-packages/airflow/providers/standard/operators/python.py","lineno":217,"name":"execute"},{"filename":"/home/airflow/.local/lib/python3.12/site-packages/airflow/providers/standard/operators/python.py","lineno":240,"name":"execute_callable"},{"filename":"/home/airflow/.local/lib/python3.12/site-packages/airflow/sdk/execution_time/callback_runner.py","lineno":81,"name":"run"},{"filename":"/opt/airflow/dags/dag_trial.py","lineno":14,"name":"print_random_quote"},{"filename":"/home/airflow/.local/lib/python3.12/site-packages/requests/api.py","lineno":73,"name":"get"},{"filename":"/home/airflow/.local/lib/python3.12/site-packages/requests/api.py","lineno":59,"name":"request"},{"filename":"/home/airflow/.local/lib/python3.12/site-packages/requests/sessions.py","lineno":589,"name":"request"},{"filename":"/home/airflow/.local/lib/python3.12/site-packages/requests/sessions.py","lineno":703,"name":"send"},{"filename":"/home/airflow/.local/lib/python3.12/site-packages/requests/adapters.py","lineno":700,"name":"send"}],"is_group":false,"exceptions":[]},{"exc_type":"MaxRetryError","exc_value":"HTTPSConnectionPool(host='api.quotable.io', port=443): Max retries exceeded with url: /random (Caused by NameResolutionError(\"<urllib3.connection.HTTPSConnection object at 0x743e7fe5c8c0>: Failed to resolve 'api.quotable.io' ([Errno -2] Name or service not known)\"))","exc_notes":[],"syntax_error":null,"is_cause":false,"frames":[{"filename":"/home/airflow/.local/lib/python3.12/site-packages/requests/adapters.py","lineno":667,"name":"send"},{"filename":"/home/airflow/.local/lib/python3.12/site-packages/urllib3/connectionpool.py","lineno":841,"name":"urlopen"},{"filename":"/home/airflow/.local/lib/python3.12/site-packages/urllib3/util/retry.py","lineno":519,"name":"increment"}],"is_group":false,"exceptions":[]},{"exc_type":"NameResolutionError","exc_value":"<urllib3.connection.HTTPSConnection object at 0x743e7fe5c8c0>: Failed to resolve 'api.quotable.io' ([Errno -2] Name or service not known)","exc_notes":[],"syntax_error":null,"is_cause":true,"frames":[{"filename":"/home/airflow/.local/lib/python3.12/site-packages/urllib3/connectionpool.py","lineno":787,"name":"urlopen"},{"filename":"/home/airflow/.local/lib/python3.12/site-packages/urllib3/connectionpool.py","lineno":488,"name":"_make_request"},{"filename":"/home/airflow/.local/lib/python3.12/site-packages/urllib3/connectionpool.py","lineno":464,"name":"_make_request"},{"filename":"/home/airflow/.local/lib/python3.12/site-packages/urllib3/connectionpool.py","lineno":1093,"name":"_validate_conn"},{"filename":"/home/airflow/.local/lib/python3.12/site-packages/urllib3/connection.py","lineno":753,"name":"connect"},{"filename":"/home/airflow/.local/lib/python3.12/site-packages/urllib3/connection.py","lineno":205,"name":"_new_conn"}],"is_group":false,"exceptions":[]},{"exc_type":"gaierror","exc_value":"[Errno -2] Name or service not known","exc_notes":[],"syntax_error":null,"is_cause":true,"frames":[{"filename":"/home/airflow/.local/lib/python3.12/site-packages/urllib3/connection.py","lineno":198,"name":"_new_conn"},{"filename":"/home/airflow/.local/lib/python3.12/site-packages/urllib3/util/connection.py","lineno":60,"name":"create_connection"},{"filename":"/usr/local/lib/python3.12/socket.py","lineno":978,"name":"getaddrinfo"}],"is_group":false,"exceptions":[]}]}

{"timestamp":"2025-08-24T14:37:50.800337","level":"error","event":"Task failed with exception","logger":"task","error_detail":[{"exc_type":"ConnectionError","exc_value":"HTTPSConnectionPool(host='api.quotable.io', port=443): Max retries exceeded with url: /random (Caused by NameResolutionError(\"<urllib3.connection.HTTPSConnection object at 0x743e5834d640>: Failed to resolve 'api.quotable.io' ([Errno -2] Name or service not known)\"))","exc_notes":[],"syntax_error":null,"is_cause":false,"frames":[{"filename":"/home/airflow/.local/lib/python3.12/site-packages/airflow/sdk/execution_time/task_runner.py","lineno":890,"name":"run"},{"filename":"/home/airflow/.local/lib/python3.12/site-packages/airflow/sdk/execution_time/task_runner.py","lineno":1177,"name":"_execute_task"},{"filename":"/home/airflow/.local/lib/python3.12/site-packages/airflow/sdk/bases/operator.py","lineno":397,"name":"wrapper"},{"filename":"/home/airflow/.local/lib/python3.12/site-packages/airflow/providers/standard/operators/python.py","lineno":217,"name":"execute"},{"filename":"/home/airflow/.local/lib/python3.12/site-packages/airflow/providers/standard/operators/python.py","lineno":240,"name":"execute_callable"},{"filename":"/home/airflow/.local/lib/python3.12/site-packages/airflow/sdk/execution_time/callback_runner.py","lineno":81,"name":"run"},{"filename":"/opt/airflow/dags/dag_trial.py","lineno":14,"name":"print_random_quote"},{"filename":"/home/airflow/.local/lib/python3.12/site-packages/requests/api.py","lineno":73,"name":"get"},{"filename":"/home/airflow/.local/lib/python3.12/site-packages/requests/api.py","lineno":59,"name":"request"},{"filename":"/home/airflow/.local/lib/python3.12/site-packages/requests/sessions.py","lineno":589,"name":"request"},{"filename":"/home/airflow/.local/lib/python3.12/site-packages/requests/sessions.py","lineno":703,"name":"send"},{"filename":"/home/airflow/.local/lib/python3.12/site-packages/requests/adapters.py","lineno":700,"name":"send"}],"is_group":false,"exceptions":[]},{"exc_type":"MaxRetryError","exc_value":"HTTPSConnectionPool(host='api.quotable.io', port=443): Max retries exceeded with url: /random (Caused by NameResolutionError(\"<urllib3.connection.HTTPSConnection object at 0x743e5834d640>: Failed to resolve 'api.quotable.io' ([Errno -2] Name or service not known)\"))","exc_notes":[],"syntax_error":null,"is_cause":false,"frames":[{"filename":"/home/airflow/.local/lib/python3.12/site-packages/requests/adapters.py","lineno":667,"name":"send"},{"filename":"/home/airflow/.local/lib/python3.12/site-packages/urllib3/connectionpool.py","lineno":841,"name":"urlopen"},{"filename":"/home/airflow/.local/lib/python3.12/site-packages/urllib3/util/retry.py","lineno":519,"name":"increment"}],"is_group":false,"exceptions":[]},{"exc_type":"NameResolutionError","exc_value":"<urllib3.connection.HTTPSConnection object at 0x743e5834d640>: Failed to resolve 'api.quotable.io' ([Errno -2] Name or service not known)","exc_notes":[],"syntax_error":null,"is_cause":true,"frames":[{"filename":"/home/airflow/.local/lib/python3.12/site-packages/urllib3/connectionpool.py","lineno":787,"name":"urlopen"},{"filename":"/home/airflow/.local/lib/python3.12/site-packages/urllib3/connectionpool.py","lineno":488,"name":"_make_request"},{"filename":"/home/airflow/.local/lib/python3.12/site-packages/urllib3/connectionpool.py","lineno":464,"name":"_make_request"},{"filename":"/home/airflow/.local/lib/python3.12/site-packages/urllib3/connectionpool.py","lineno":1093,"name":"_validate_conn"},{"filename":"/home/airflow/.local/lib/python3.12/site-packages/urllib3/connection.py","lineno":753,"name":"connect"},{"filename":"/home/airflow/.local/lib/python3.12/site-packages/urllib3/connection.py","lineno":205,"name":"_new_conn"}],"is_group":false,"exceptions":[]},{"exc_type":"gaierror","exc_value":"[Errno -2] Name or service not known","exc_notes":[],"syntax_error":null,"is_cause":true,"frames":[{"filename":"/home/airflow/.local/lib/python3.12/site-packages/urllib3/connection.py","lineno":198,"name":"_new_conn"},{"filename":"/home/airflow/.local/lib/python3.12/site-packages/urllib3/util/connection.py","lineno":60,"name":"create_connection"},{"filename":"/usr/local/lib/python3.12/socket.py","lineno":978,"name":"getaddrinfo"}],"is_group":false,"exceptions":[]}]}

